<?xml version="1.0" ?>
<robot name="finger0">
	<link name="base">
        <inertial>
            <origin xyz="0.0 0.0 0.0" rpy="0 0 0"/>
            <mass value="0.0001"/>
            <inertia ixx="0.00003"  iyy="0.000084" izz="0.000088" ixy="0"  ixz="0" iyz="0"/>
        </inertial>
    </link>
	<link name="finger0-link0">
        <inertial>
            <origin xyz="0 -0.018 -0.01" rpy="0 0 0"/>
            <mass value="0.0716"/>
            <inertia ixx="0.00003"  iyy="0.000084" izz="0.000088" ixy="0"  ixz="0" iyz="0"/>
        </inertial>
        <visual>
            <origin xyz="0 -0.018 -0.01" rpy="0 0 0" />
            <geometry>
                <box size="0.036 0.036 0.036" />
            </geometry>
            <material name="material_white">
                <color rgba="0.7 0.7 0.7 1.0" />
            </material>
        </visual>
    </link>

    <link name="finger0-link1">
        <inertial>
            <origin xyz="0.0 -0.0075 0" rpy="0 0 0"/>
            <mass value="0.01"/>
            <inertia ixx="0.000003"  iyy="0.0000084" izz="0.0000088" ixy="0"  ixz="0" iyz="0"/>
        </inertial>
        <visual>
            <origin xyz="0.0 -0.0075 0" rpy="0 0 0" />
            <geometry>
                <box size="0.016 0.015 0.025" />
            </geometry>
            <material name="material_orange">
                <color rgba="0.9 0.6 0.1 1.0" />
            </material>
        </visual>
    </link>

    <link name="finger0-link2">
        <inertial>
            <origin xyz="0.0192 0 0" rpy="0 0 0"/>
            <mass value="0.0509"/>
            <inertia ixx="0.000024"  iyy="0.000036" izz="0.000038" ixy="0"  ixz="0" iyz="0"/>
        </inertial>
        <visual>
            <origin xyz="0.025 0.0 0.0" rpy="0 0 0" />
            <geometry>
                <box size="0.05 0.0168 0.025" />
            </geometry>
            <material name="material_green">
                <color rgba="0.3 0.6 0.3 1.0" />
            </material>
        </visual>
    </link>

    <link name="finger0-link3">
        <inertial>
            <origin xyz="0.0327 0 0" rpy="0 0 0"/>
            <mass value="0.047"/>
            <inertia ixx="0.00001"  iyy="0.00001" izz="0.00002" ixy="0"  ixz="0" iyz="0"/>
        </inertial>
        <visual>
            <origin xyz="0.0507 0.0 0.0" rpy="0 0 0" />
            <geometry>
                <sphere radius="0.014" />
            </geometry>
            <material name="material_light_blue">
                <color rgba="0.4 0.4 0.7 1.0" />
            </material>
        </visual>
        <visual>
            <origin xyz="0.01835 0.0 0.0" rpy="0 0 0" />
            <geometry>
                <box size="0.0367 0.028 0.025" />
            </geometry>
            <material name="material_light_blue">
                <color rgba="0.4 0.4 0.7 1.0" />
            </material>
        </visual>
        <collision>
            <origin xyz="0.0507 0.0 0.0" rpy="0 0 0" />
            <geometry>
                <sphere radius="0.014" />
            </geometry>
        </collision>
    </link>


<!-- joint -->
    <joint name="finger0-j0" type="revolute">
        <parent link="base" />
        <child link="finger0-link0" />
        <origin xyz="-0.0155 -0.015 -0.008" rpy="0.1 0 0"/>
        <axis xyz="1 0 0" />
        <limit lower="-2.967" upper="2.967" effort="176" velocity="1.7104" />
    </joint>

    <joint name="finger0-j1" type="revolute">
        <parent link="finger0-link0" />
        <child link="finger0-link1" />
        <origin xyz="-0.01 -0.036 0" rpy="0 0.1 0"/>
        <axis xyz="0 1 0" />
        <limit lower="-2.967" upper="2.967" effort="176" velocity="1.7104" />
    </joint>

    <joint name="finger0-j2" type="revolute">
        <parent link="finger0-link1" />
        <child link="finger0-link2" />
        <origin xyz="0 -0.015 0" rpy="0 0 0.2"/>
        <axis xyz="0 0 1" />
        <limit lower="-2.967" upper="2.967" effort="176" velocity="1.7104" />
    </joint>

    <joint name="finger0-j3" type="revolute">
        <parent link="finger0-link2" />
        <child link="finger0-link3" />
        <origin xyz="0.05 0 0" rpy="0 0 0.2"/>
        <axis xyz="0 0 1" />
        <limit lower="-2.967" upper="2.967" effort="176" velocity="1.7104" />
    </joint>
</robot>